<robot name="box">
<link name="robot_base">
<visual>
<origin xyz="0 0 0.25" rpy="0 0 0" />
<geometry>
<box size="0.5 0.5 0.5" />
</geometry>
<material name="blau">
<color rgba="0 0 1 1" />
</material>
</visual>
</link>
<link name="link_rad">
<visual>
<origin xyz="0 0 0" rpy="0 0 0" />
<geometry>
<cylinder radius="0.1" length="0.1"/>
</geometry>
<material name="red">
<color rgba="1 0 0 1" />
</material>
</visual>
</link>
<link name="recht_rad">
<visual>
<origin xyz="0 0 0" rpy="0 0 0" />
<geometry>
<cylinder radius="0.1" length="0.1"/>
</geometry>
<material name="red">
<color rgba="1 0 0 1" />
</material>
</visual>
</link>
<joint name="hand_base2link_rad" type="continuous">
<parent link="robot_base"/>
<child link="link_rad" />
<origin xyz="0 0.3 0" rpy="1.57 0 0" />
<axis xyz="0 0 1" />
</joint>
<joint name="hand_base2recht_rad" type="continuous">
<parent link="robot_base"/>
<child link="recht_rad" />
<origin xyz="0 -0.3 0" rpy="1.57 0 0" />
<axis xyz="0 0 1" />
</joint>
</robot>