<robot name="model_o" xmlns:xacro="http://ros.org/wiki/xacro">

  <!-- Define common properties for links -->
  <!-- hand_coupler -->
  <xacro:property name="hand_coupler_inertial_xyz" value="0.000000 0.000000 0.025400"/>
  <xacro:property name="hand_coupler_mass" value="10"/>
  <xacro:property name="hand_coupler_inertia_ixx" value="1000"/>
  <xacro:property name="hand_coupler_inertia_ixy" value="0"/>
  <xacro:property name="hand_coupler_inertia_ixz" value="0"/>
  <xacro:property name="hand_coupler_inertia_iyy" value="1000"/>
  <xacro:property name="hand_coupler_inertia_iyz" value="0"/>
  <xacro:property name="hand_coupler_inertia_izz" value="1000"/>
  <xacro:property name="hand_coupler_color" value="0. 0.3 1.0 1.0"/>
  <xacro:property name="hand_coupler_common_rpy" value="0 1.57079632679 0"/>
  <xacro:property name="hand_coupler_common_xyz" value="0.000000 0.000000 0.000000"/>
  <xacro:property name="hand_coupler_size" value="0.098 0.113 0.00762"/>
  <!-- motor_space -->
  <xacro:property name="motor_space_inertial_xyz" value="0.000000 0.000000 0.025400"/>
  <xacro:property name="motor_space_mass" value="10"/>
  <xacro:property name="motor_space_inertia_ixx" value="1000"/>
  <xacro:property name="motor_space_inertia_ixy" value="0"/>
  <xacro:property name="motor_space_inertia_ixz" value="0"/>
  <xacro:property name="motor_space_inertia_iyy" value="1000"/>
  <xacro:property name="motor_space_inertia_iyz" value="0"/>
  <xacro:property name="motor_space_inertia_izz" value="1000"/>
  <xacro:property name="motor_space_color" value="0. 0. 0. 1.0"/>
  <xacro:property name="motor_space_common_rpy" value="0 1.57079632679 0"/>
  <xacro:property name="motor_space_common_xyz" value="0.000000 0.000000 0.000000"/>
  <xacro:property name="motor_space_size" value="0.098 0.113 0.06"/>
  <!-- simple_base -->
  <xacro:property name="simple_base_inertial_xyz" value="0.000000 0.000000 0.025400"/>
  <xacro:property name="simple_base_mass" value="10"/>
  <xacro:property name="simple_base_inertia_ixx" value="1000"/>
  <xacro:property name="simple_base_inertia_ixy" value="0"/>
  <xacro:property name="simple_base_inertia_ixz" value="0"/>
  <xacro:property name="simple_base_inertia_iyy" value="1000"/>
  <xacro:property name="simple_base_inertia_iyz" value="0"/>
  <xacro:property name="simple_base_inertia_izz" value="1000"/>
  <xacro:property name="simple_base_color" value="0. 0.3 1.0 1.0"/>
  <xacro:property name="simple_base_common_rpy" value="0 1.57079632679 0"/>
  <xacro:property name="simple_base_common_xyz" value="0.000000 0.000000 0.000000"/>
  <xacro:property name="simple_base_size" value="0.098 0.128 0.003"/>
  <!-- prox -->
  <xacro:property name="prox_inertial_xyz" value="-0.015875 -0.009000 -0.071550"/>
  <xacro:property name="prox_mass" value="1.0"/>
  <xacro:property name="prox_inertia_ixx" value="1"/>
  <xacro:property name="prox_inertia_ixy" value="0"/>
  <xacro:property name="prox_inertia_ixz" value="0"/>
  <xacro:property name="prox_inertia_iyy" value="1"/>
  <xacro:property name="prox_inertia_iyz" value="0"/>
  <xacro:property name="prox_inertia_izz" value="1"/>
  <xacro:property name="prox_color" value="1.0 1.0 1.0 1.0"/>
  <xacro:property name="prox_origin_rpy" value="0 -3.141592 2.4"/>
  <xacro:property name="prox_origin_xyz" value="-0.00 0.0753 0.008"/>
  <xacro:property name="prox_mesh_scala" value="0.00100 0.00100 0.00100"/>
  <xacro:property name="prox_collision_rpy" value="1.5707 0 0"/>
  <xacro:property name="prox_collision_xyz" value="0.00 0.032 0.00"/>
  <xacro:property name="prox_size" value="0.02400 0.018 0.08340"/>
  <!-- distal -->
  <xacro:property name="distal_inertial_xyz" value="-0.015875 -0.009000 -0.071550"/>
  <xacro:property name="distal_mass" value="1.0"/>
  <xacro:property name="distal_inertia_ixx" value="1"/>
  <xacro:property name="distal_inertia_ixy" value="0"/>
  <xacro:property name="distal_inertia_ixz" value="0"/>
  <xacro:property name="distal_inertia_iyy" value="1"/>
  <xacro:property name="distal_inertia_iyz" value="0"/>
  <xacro:property name="distal_inertia_izz" value="1"/>
  <xacro:property name="distal_color" value="1.0 1.0 1.0 1.0"/> 
  <xacro:property name="distal_origin_rpy" value="0 0 -2.4962"/>
  <xacro:property name="distal_origin_xyz" value="-0.0179 0.0459 -0.008"/>
  <xacro:property name="distal_mesh_scala" value="0.00100 0.00100 0.00100"/>
  <xacro:property name="distal_collision_rpy" value="0 0 -2.4962"/>
  <xacro:property name="distal_collision_xyz" value="-0.0179 0.0459 -0.008"/>
  <!-- prox_rotate -->
  <xacro:property name="prox_rotate_inertial_xyz" value="-0.015875 -0.009000 -0.071550"/>
  <xacro:property name="prox_rotate_mass" value="1.0"/>
  <xacro:property name="prox_rotate_inertia_ixx" value="1"/>
  <xacro:property name="prox_rotate_inertia_ixy" value="0"/>
  <xacro:property name="prox_rotate_inertia_ixz" value="0"/>
  <xacro:property name="prox_rotate_inertia_iyy" value="1"/>
  <xacro:property name="prox_rotate_inertia_iyz" value="0"/>
  <xacro:property name="prox_rotate_inertia_izz" value="1"/>
  <xacro:property name="prox_rotate_color" value="1.0 1.0 1.0 1.0"/>
  <xacro:property name="prox_rotate_origin_rpy" value="0 1.57 0"/>
  <xacro:property name="prox_rotate_origin_xyz" value="-0.00 0.0 0.00"/>
  <xacro:property name="prox_rotate_collision_rpy" value="0 1.57 0"/>
  <xacro:property name="prox_rotate_collision_xyz" value="0.00 0.0 0.00"/> 
  <xacro:property name="prox_rotate_size_length" value="0.002"/>
  <xacro:property name="prox_rotate_size_radius" value="0.018"/>  
  <!-- Define common properties for joints -->
  <!-- fixed1 -->
  <xacro:property name="fixed1_rpy" value="0 1.57 0"/>
  <xacro:property name="fixed1_xyz" value="-0.000381 0.0000 0.000000"/>
  <!-- fixed2 -->
  <xacro:property name="fixed2_rpy" value="0 0 0"/>
  <xacro:property name="fixed2_xyz" value="-0.03381 0.000000 0.000000"/>
  <!-- fixed3 -->
  <xacro:property name="fixed3_rpy" value="0 0 0"/>
  <xacro:property name="fixed3_xyz" value="-0.0315 -0.0075 0.000000"/>
  <!-- base_to_prox_t -->
  <xacro:property name="base_to_prox_t_rpy" value="0 0 0"/>
  <xacro:property name="base_to_prox_t_xyz" value="-0.023 0.034 0.000000"/>
  <xacro:property name="base_to_prox_t_limit_effort" value="10000"/>
  <xacro:property name="base_to_prox_t_limit_lower" value="0"/>
  <xacro:property name="base_to_prox_t_limit_upper" value="3"/>
  <xacro:property name="base_to_prox_t_limit_velocity" value="200"/>
  <xacro:property name="base_to_prox_t_damping" value="160"/>
  <xacro:property name="base_to_prox_t_friction" value="0"/>
  <!-- prox_to_distal_t -->
  <xacro:property name="prox_to_distal_t_rpy" value="0 0 0"/>
  <xacro:property name="prox_to_distal_t_xyz" value="0.000800 0.062 0"/>
  <xacro:property name="prox_to_distal_t_limit_effort" value="10000"/>
  <xacro:property name="prox_to_distal_t_limit_lower" value="0"/>
  <xacro:property name="prox_to_distal_t_limit_upper" value="1.24"/>
  <xacro:property name="prox_to_distal_t_limit_velocity" value="200"/>
  <xacro:property name="prox_to_distal_t_damping" value="300"/>
  <xacro:property name="prox_to_distal_t_friction" value="0"/>
  <!-- base_to_rot_l -->
  <xacro:property name="base_to_rot_l_rpy" value="4.7123899 0 0"/>
  <xacro:property name="base_to_rot_l_xyz" value="-0.003 -0.034 -0.027"/>
  <xacro:property name="base_to_rot_l_limit_effort" value="10000"/>
  <xacro:property name="base_to_rot_l_limit_lower" value="-1.570"/>
  <xacro:property name="base_to_rot_l_limit_upper" value="0"/>
  <xacro:property name="base_to_rot_l_limit_velocity" value="200"/>
  <xacro:property name="base_to_rot_l_damping" value="160"/>
  <xacro:property name="base_to_rot_l_friction" value="0"/>
  <!-- rot_to_prox_l -->
  <xacro:property name="rot_to_prox_l_rpy" value="0 0 0"/>
  <xacro:property name="rot_to_prox_l_xyz" value="-0.02 0 0"/>
  <xacro:property name="rot_to_prox_l_limit_effort" value="10000"/>
  <xacro:property name="rot_to_prox_l_limit_lower" value="0"/>
  <xacro:property name="rot_to_prox_l_limit_upper" value="3"/>
  <xacro:property name="rot_to_prox_l_limit_velocity" value="200"/>
  <xacro:property name="rot_to_prox_l_damping" value="160"/>
  <xacro:property name="rot_to_prox_l_friction" value="0"/>
  <!-- prox_to_distal_l -->
  <xacro:property name="prox_to_distal_l_rpy" value="0 0 0"/>
  <xacro:property name="prox_to_distal_l_xyz" value="0.000800 0.062 0"/>
  <xacro:property name="prox_to_distal_l_limit_effort" value="10000"/>
  <xacro:property name="prox_to_distal_l_limit_lower" value="0"/>
  <xacro:property name="prox_to_distal_l_limit_upper" value="1.24"/>
  <xacro:property name="prox_to_distal_l_limit_velocity" value="200"/>
  <xacro:property name="prox_to_distal_l_damping" value="300"/>
  <xacro:property name="prox_to_distal_l_friction" value="0"/>
  <!-- base_to_rot_r -->
  <xacro:property name="base_to_rot_r_rpy" value="1.5708 0 0"/>
  <xacro:property name="base_to_rot_r_xyz" value="-0.003 -0.034 0.027"/>
  <xacro:property name="base_to_rot_r_limit_effort" value="10000"/>
  <xacro:property name="base_to_rot_r_limit_lower" value="0"/>
  <xacro:property name="base_to_rot_r_limit_upper" value="1.57"/>
  <xacro:property name="base_to_rot_r_limit_velocity" value="200"/>
  <xacro:property name="base_to_rot_r_damping" value="160"/>
  <xacro:property name="base_to_rot_r_friction" value="0"/>
  <!-- rot_to_prox_r -->
  <xacro:property name="rot_to_prox_r_rpy" value="0 0 0"/>
  <xacro:property name="rot_to_prox_r_xyz" value="-0.02 0 0"/>
  <xacro:property name="rot_to_prox_r_limit_effort" value="10000"/>
  <xacro:property name="rot_to_prox_r_limit_lower" value="0"/>
  <xacro:property name="rot_to_prox_r_limit_upper" value="3"/>
  <xacro:property name="rot_to_prox_r_limit_velocity" value="200"/>
  <xacro:property name="rot_to_prox_r_damping" value="160"/>
  <xacro:property name="rot_to_prox_r_friction" value="0"/>
  <!-- prox_to_distal_r -->
  <xacro:property name="prox_to_distal_r_rpy" value="0 0 0"/>
  <xacro:property name="prox_to_distal_r_xyz" value="0.000800 0.062 0"/>
  <xacro:property name="prox_to_distal_r_limit_effort" value="10000"/>
  <xacro:property name="prox_to_distal_r_limit_lower" value="0"/>
  <xacro:property name="prox_to_distal_r_limit_upper" value="1.24"/>
  <xacro:property name="prox_to_distal_r_limit_velocity" value="200"/>
  <xacro:property name="prox_to_distal_r_damping" value="300"/>
  <xacro:property name="prox_to_distal_r_friction" value="0"/>
  <!-- Links -->
  <link name="hand_base"/>

  <!-- hand_coupler -->
  <link name="hand_coupler">
    <inertial>
      <origin xyz="${hand_coupler_inertial_xyz}"/>
      <mass value="${hand_coupler_mass}"/>
      <inertia ixx="${simple_base_inertia_ixx}" ixy="${simple_base_inertia_ixy}" ixz="${simple_base_inertia_ixz}" iyy="${simple_base_inertia_iyy}" iyz="${simple_base_inertia_iyz}" izz="${simple_base_inertia_izz}"/>
    </inertial>
    <visual>
      <material name="lightlue">
        <color rgba="${hand_coupler_color}"/>
      </material>
      <origin rpy="${hand_coupler_common_rpy}" xyz="${hand_coupler_common_xyz}"/>
      <geometry>
        <box size="${hand_coupler_size}"/>
      </geometry>
    </visual>
    <collision>
      <origin rpy="${hand_coupler_common_rpy}" xyz="${hand_coupler_common_xyz}"/>
      <geometry>
        <box size="${hand_coupler_size}"/>
      </geometry>
    </collision>
  </link>
  <!-- motor_space -->
  <link name="motor_space">
    <inertial>
      <origin xyz="${motor_space_inertial_xyz}"/>
      <mass value="${motor_space_mass}"/>
      <inertia ixx="${motor_space_inertia_ixx}" ixy="${motor_space_inertia_ixy}" ixz="${motor_space_inertia_ixz}" iyy="${motor_space_inertia_iyy}" iyz="${motor_space_inertia_iyz}" izz="${motor_space_inertia_izz}"/>
    </inertial>
    <visual>
      <material name="black">
        <color rgba="${motor_space_color}"/>
      </material>
      <origin rpy="${motor_space_common_rpy}" xyz="${motor_space_common_xyz}"/>
      <geometry>
        <box size = "${motor_space_size}"/>
      </geometry>
    </visual>
    <collision>
      <origin rpy="${motor_space_common_rpy}" xyz="${motor_space_common_xyz}"/>
      <geometry>
        <box size = "${motor_space_size}"/>
      </geometry>
    </collision>
  </link>
  <!-- simple_base -->
  <link name="simple_base">
    <inertial>
      <origin xyz="${simple_base_inertial_xyz}"/>
      <mass value="${simple_base_mass}"/>
      <inertia ixx="${simple_base_inertia_ixx}" ixy="${simple_base_inertia_ixy}" ixz="${simple_base_inertia_ixz}" iyy="${simple_base_inertia_iyy}" iyz="${simple_base_inertia_iyz}" izz="${simple_base_inertia_izz}"/>
    </inertial>
    <visual>
      <material name="lightlue">
        <color rgba="${simple_base_color}"/>
      </material>
      <origin rpy="${simple_base_common_rpy}" xyz="${simple_base_common_xyz}"/>
      <geometry>
        <box size = "${simple_base_size}"/>
      </geometry>
    </visual>
    <collision>
      <origin rpy="${simple_base_common_rpy}" xyz="${simple_base_common_xyz}"/>
      <geometry>
        <box size = "${simple_base_size}"/>
      </geometry>
    </collision>
  </link>
  <!-- prox macros -->
  <xacro:macro name="prox" params="name">
      <link name="prox_${name}">
          <inertial>
              <origin xyz="${prox_inertial_xyz}" />
              <mass value="${prox_mass}" />
              <inertia ixx="${prox_inertia_ixx}" ixy="${prox_inertia_ixy}" ixz="${prox_inertia_ixz}" iyy="${prox_inertia_iyy}" iyz="${prox_inertia_iyz}" izz="${prox_inertia_izz}" />
          </inertial>
          <visual>
              <material name="white">
                  <color rgba="${prox_color}" />
              </material>
              <origin rpy="${prox_origin_rpy}" xyz="${prox_origin_xyz}" />
              <geometry>
                  <mesh filename="package://openhand_simulation/model_o/proximal.STL" scale="${prox_mesh_scala}" />
              </geometry>
          </visual>
          <collision>
              <origin rpy="${prox_collision_rpy}" xyz="${prox_collision_xyz}" />
              <geometry>
                  <box size="${prox_size}" />
              </geometry>
          </collision>
      </link>
  </xacro:macro>
  <!-- call macro function  -->
  <xacro:prox name="t"/>
  <xacro:prox name="l"/>
  <xacro:prox name="r"/>
  <!--  distal macros -->
  <xacro:macro name="distal" params="name">
      <link name="distal_${name}">
          <inertial>
              <origin xyz="${distal_inertial_xyz}" />
              <mass value="${distal_mass}" />
              <inertia ixx="${distal_inertia_ixx}" ixy="${distal_inertia_ixy}" ixz="${distal_inertia_ixz}" iyy="${distal_inertia_iyy}" iyz="${distal_inertia_iyz}" izz="${distal_inertia_izz}" />
          </inertial>
          <visual>
              <material name="white">
                  <color rgba="${distal_color}" />
              </material>
              <origin rpy="${distal_origin_rpy}" xyz="${distal_origin_xyz}" />
              <geometry>
                  <mesh filename="package://openhand_simulation/model_o/distal.STL" scale="${distal_mesh_scala}" />
              </geometry>
          </visual>
          <collision>
              <origin rpy="${distal_collision_rpy}" xyz="${distal_collision_xyz}" />
              <geometry>
                  <mesh filename="package://openhand_simulation/model_o/distal.STL" scale="${distal_mesh_scala}" />
              </geometry>
          </collision>
      </link>
  </xacro:macro>

  <!-- call distal macro func -->
  <xacro:distal name="t"/>
  <xacro:distal name="l"/>
  <xacro:distal name="r"/>

  <!-- prox_rotate macro -->
  <xacro:macro name="prox_rotate" params="name">
    <link name="prox_rotate_${name}">
    <inertial>
        <origin xyz="${prox_rotate_inertial_xyz}"/>
        <mass value="${prox_rotate_mass}"/>
        <inertia ixx="${prox_rotate_inertia_ixx}" ixy="${prox_rotate_inertia_ixy}" ixz="${prox_rotate_inertia_ixz}" iyy="${prox_rotate_inertia_iyy}" iyz="${prox_rotate_inertia_iyz}" izz="${prox_rotate_inertia_izz}"/>
    </inertial>
    <visual>
        <material name="white">
            <color rgba="${prox_rotate_color}"/>
        </material>
        <origin rpy="${prox_rotate_origin_rpy}" xyz="${prox_rotate_origin_xyz}"/>
        <geometry>
            <cylinder length="${prox_rotate_size_length}" radius="${prox_rotate_size_radius}"/>
        </geometry>
    </visual>
    <collision>
      <origin rpy="${prox_rotate_collision_rpy}" xyz="${prox_rotate_collision_xyz}" />
      <geometry>
        <cylinder length="${prox_rotate_size_length}" radius="${prox_rotate_size_radius}" />
      </geometry>
    </collision>
    </link>
  </xacro:macro>
  <!-- call prox_rotate macro func -->
  <xacro:prox_rotate name="l"/>
  <xacro:prox_rotate name="r"/>
  
  <!-- joints -->
<joint name="fixed1" type="fixed">
    <origin rpy="${fixed1_rpy}" xyz="${fixed1_xyz}"/>
    <parent link="hand_base"/>
    <child link="hand_coupler"/>
</joint>

<joint name="fixed2" type="fixed">
    <origin rpy="${fixed2_rpy}" xyz="${fixed2_xyz}"/>
    <parent link="hand_coupler"/>
    <child link="motor_space"/>
</joint>

<joint name="fixed3" type="fixed">
    <origin rpy="${fixed3_rpy}" xyz="${fixed3_xyz}"/>
    <parent link="motor_space"/>
    <child link="simple_base"/>
</joint>

<joint name="base_to_prox_t" type="revolute">
    <origin rpy="${base_to_prox_t_rpy}" xyz="${base_to_prox_t_xyz}" />
    <parent link="simple_base" />
    <child link="prox_t" />
    <limit effort="${base_to_prox_t_limit_effort}" lower="${base_to_prox_t_limit_lower}" upper="${base_to_prox_t_limit_upper}" velocity="${base_to_prox_t_limit_velocity}" />
    <axis xyz="0 0 1" />
    <dynamics damping="${base_to_prox_t_damping}" friction="${base_to_prox_t_friction}" />
</joint>

<joint name="prox_to_distal_t" type="revolute">
    <origin rpy="${prox_to_distal_t_rpy}" xyz="${prox_to_distal_t_xyz}" />
    <parent link="prox_t" />
    <child link="distal_t" />
    <limit effort="${prox_to_distal_t_limit_effort}" lower="${prox_to_distal_t_limit_lower}" upper="${prox_to_distal_t_limit_upper}" velocity="${prox_to_distal_t_limit_velocity}" />
    <axis xyz="0 0 1" />
    <dynamics damping="${prox_to_distal_t_damping}" friction="${prox_to_distal_t_friction}" />
</joint>

<joint name="base_to_rot_l" type="revolute">
   <origin rpy="${base_to_rot_l_rpy}" xyz="${base_to_rot_l_xyz}" />
   <parent link="simple_base" />
   <child link="prox_rotate_l" />
   <limit effort="${base_to_rot_l_limit_effort}" lower="${base_to_rot_l_limit_lower}" upper="${base_to_rot_l_limit_upper}" velocity="${base_to_rot_l_limit_velocity}" />
   <axis xyz="1 0 0" />
   <dynamics damping="${base_to_rot_l_damping}" friction="${base_to_rot_l_friction}" />
</joint>

<joint name="rot_to_prox_l" type="revolute">
   <origin rpy="${rot_to_prox_l_rpy}" xyz="${rot_to_prox_l_xyz}" />
   <parent link="prox_rotate_l" />
   <child link="prox_l" />
   <limit effort="${rot_to_prox_l_limit_effort}" lower="${rot_to_prox_l_limit_lower}" upper="${rot_to_prox_l_limit_upper}" velocity="${rot_to_prox_l_limit_velocity}" />
   <axis xyz="0 0 1" />
   <dynamics damping="${rot_to_prox_l_damping}" friction="${rot_to_prox_l_friction}" />
</joint>

<joint name="prox_to_distal_l" type="revolute">
   <origin rpy="${prox_to_distal_l_rpy}" xyz="${prox_to_distal_l_xyz}" />
   <parent link="prox_l" />
   <child link="distal_l" />
   <limit effort="${prox_to_distal_l_limit_effort}" lower="${prox_to_distal_l_limit_lower}" upper="${prox_to_distal_l_limit_upper}" velocity="${prox_to_distal_l_limit_velocity}" />
   <axis xyz="0 0 1" />
   <dynamics damping="${prox_to_distal_l_damping}" friction="${prox_to_distal_l_friction}" />
</joint>

<joint name="base_to_rot_r" type="revolute">
  <origin rpy="${base_to_rot_r_rpy}" xyz="${base_to_rot_r_xyz}" />
  <parent link="simple_base" />
  <child link="prox_rotate_r" />
  <limit effort="${base_to_rot_r_limit_effort}" lower="${base_to_rot_r_limit_lower}" upper="${base_to_rot_r_limit_upper}" velocity="${base_to_rot_r_limit_velocity}" />
  <axis xyz="1 0 0" />
  <dynamics damping="${base_to_rot_r_damping}" friction="${base_to_rot_r_friction}" />
</joint>

<joint name="rot_to_prox_r" type="revolute">
  <origin rpy="${rot_to_prox_r_rpy}" xyz="${rot_to_prox_r_xyz}" />
  <parent link="prox_rotate_r" />
  <child link="prox_r" />
  <limit effort="${rot_to_prox_r_limit_effort}" lower="${rot_to_prox_r_limit_lower}" upper="${rot_to_prox_r_limit_upper}" velocity="${rot_to_prox_r_limit_velocity}" />
  <axis xyz="0 0 1" />
  <dynamics damping="${rot_to_prox_r_damping}" friction="${rot_to_prox_r_friction}" />
</joint>


<joint name="prox_to_distal_r" type="revolute">
  <origin rpy="${prox_to_distal_r_rpy}" xyz="${prox_to_distal_r_xyz}" />
  <parent link="prox_r" />
  <child link="distal_r" />
  <limit effort="${prox_to_distal_r_limit_effort}" lower="${prox_to_distal_r_limit_lower}" upper="${prox_to_distal_r_limit_upper}" velocity="${prox_to_distal_r_limit_velocity}" />
  <axis xyz="0 0 1" />
  <dynamics damping="${prox_to_distal_r_damping}" friction="${prox_to_distal_r_friction}" />
</joint>
<!-- Transmissions -->
<transmission name="tran11">
    <type>transmission_interface/SimpleTransmission</type>
    <joint name="base_to_prox_t">
      <hardwareInterface>hardware_interface/PositionJointInterface</hardwareInterface>
    </joint>
    <actuator name="motor11">
      <hardwareInterface>hardware_interface/PositionJointInterface</hardwareInterface>
      <mechanicalReduction>1</mechanicalReduction>
    </actuator>
</transmission>

<transmission name="tran12">
  <type>transmission_interface/SimpleTransmission</type>
  <joint name="prox_to_distal_t">
    <hardwareInterface>hardware_interface/PositionJointInterface</hardwareInterface>
  </joint>
  <actuator name="motor12">
    <hardwareInterface>hardware_interface/PositionJointInterface</hardwareInterface>
    <mechanicalReduction>1</mechanicalReduction>
  </actuator>
</transmission>

<transmission name="tran13">
  <type>transmission_interface/SimpleTransmission</type>
  <joint name="rot_to_prox_r">
    <hardwareInterface>hardware_interface/PositionJointInterface</hardwareInterface>
  </joint>
  <actuator name="motor13">
    <hardwareInterface>hardware_interface/PositionJointInterface</hardwareInterface>
    <mechanicalReduction>1</mechanicalReduction>
  </actuator>
</transmission>

<transmission name="tran14">
  <type>transmission_interface/SimpleTransmission</type>
  <joint name="prox_to_distal_r">
    <hardwareInterface>hardware_interface/PositionJointInterface</hardwareInterface>
  </joint>
  <actuator name="motor14">
    <hardwareInterface>hardware_interface/PositionJointInterface</hardwareInterface>
    <mechanicalReduction>1</mechanicalReduction>
  </actuator>
</transmission>

<transmission name="tran15">
  <type>transmission_interface/SimpleTransmission</type>
  <joint name="rot_to_prox_l">
    <hardwareInterface>hardware_interface/PositionJointInterface</hardwareInterface>
  </joint>
  <actuator name="motor15">
    <hardwareInterface>hardware_interface/PositionJointInterface</hardwareInterface>
    <mechanicalReduction>1</mechanicalReduction>
  </actuator>
</transmission>

<transmission name="tran15">
  <type>transmission_interface/SimpleTransmission</type>
  <joint name="prox_to_distal_l">
    <hardwareInterface>hardware_interface/PositionJointInterface</hardwareInterface>
  </joint>
  <actuator name="motor15">
    <hardwareInterface>hardware_interface/PositionJointInterface</hardwareInterface>
    <mechanicalReduction>1</mechanicalReduction>
  </actuator>
</transmission>

<transmission name="tran16">
  <type>transmission_interface/SimpleTransmission</type>
  <joint name="base_to_rot_r">
    <hardwareInterface>hardware_interface/PositionJointInterface</hardwareInterface>
  </joint>
  <actuator name="motor16">
    <hardwareInterface>hardware_interface/PositionJointInterface</hardwareInterface>
    <mechanicalReduction>1</mechanicalReduction>
  </actuator>
</transmission>

<transmission name="tran17">
  <type>transmission_interface/SimpleTransmission</type>
  <joint name="base_to_rot_l">
    <hardwareInterface>hardware_interface/PositionJointInterface</hardwareInterface>
  </joint>
  <actuator name="motor17">
    <hardwareInterface>hardware_interface/PositionJointInterface</hardwareInterface>
    <mechanicalReduction>1</mechanicalReduction>
  </actuator>
</transmission>

  <!-- Gazebo properties -->
<gazebo reference="hand_coupler">
  <material>Gazebo/SkyBlue</material>
  <selfCollide>false</selfCollide>
</gazebo>

<gazebo reference="motor_space">
  <material>Gazebo/Black</material>
  <selfCollide>false</selfCollide>
</gazebo>

<gazebo reference="simple_base">
  <material>Gazebo/SkyBlue</material>
  <selfCollide>false</selfCollide>
</gazebo>

<gazebo reference="prox_rotate_l">
  <material>Gazebo/White</material>
  <selfCollide>false</selfCollide>
</gazebo>

<gazebo reference="prox_rotate_r">
  <material>Gazebo/White</material>
  <selfCollide>false</selfCollide>
</gazebo>

<gazebo reference="prox_r">
  <material>Gazebo/White</material>
  <selfCollide>false</selfCollide>
</gazebo>

<gazebo reference="prox_l">
  <material>Gazebo/White</material>
  <selfCollide>false</selfCollide>
</gazebo>

<gazebo reference="prox_t">
  <material>Gazebo/White</material>
  <selfCollide>false</selfCollide>
</gazebo>

<gazebo reference="distal_r">
  <material>Gazebo/Green</material>
  <selfCollide>false</selfCollide>
  <mu1>100000000</mu1>
  <mu2>100000000</mu2>
</gazebo>

<gazebo reference="distal_l">
  <material>Gazebo/Orange</material>
  <selfCollide>false</selfCollide>
  <mu1>100000000</mu1>
  <mu2>100000000</mu2>
</gazebo>

<gazebo reference="distal_t">
  <material>Gazebo/Orange</material>
  <selfCollide>false</selfCollide>
  <mu1>100000000</mu1>
  <mu2>100000000</mu2>
</gazebo>

<gazebo>
  <plugin name="gazebo_ros_control" filename="libgazebo_ros_control.so">
    <robotNamespace>/model_o</robotNamespace>
    <commandTopic>cmd_vel</commandTopic>
    <robotSimType>gazebo_ros_control/DefaultRobotHWSim</robotSimType>
  </plugin>
</gazebo>





</robot>
